Workbook

Sheet Dashboard
A1: Mbappe Group of Hotels | Dashboard | Revenue - 2025
A4: Liffey Quarter Hotels - | C4: 150 rooms
A5: Hotel California - | C5: 125 rooms
A6: Property: | B6: Hotel California
A8: YTD RevPAR (€) | C8: Average ADR (€) | E8: Overall Occupancy | G8: CompSet Rate Index
A9: ='Monthly Data'!G16 -> 181.26569 | C9: ='Monthly Data'!F16 -> 220.12901 | E9: ='Monthly Data'!E16 -> 0.82345205 | G9: ='Monthly Data'!J16 -> 119.1139

Sheet Hotel Data
A1: Date | B1: Property | C1: Month | D1: Season | E1: Day | F1: Rooms Sold | G1: Total Rooms Available | H1: Room Revenue (€) | I1: Competitor Set Avg Rate (€) | J1: Occupancy % | K1: ADR (€) | L1: RevPAR (€) | M1: Rate Variance vs CompSet (€) | N1: Event / Demand Driver
A2: 45658 | B2: Liffey Quarter Hotel | C2: =CHOOSE(MONTH(A2),"Jan","Feb","Mar","Apr","May","Jun","Jul","Aug","Sep","Oct","Nov","Dec") -> Jan | D2: =IF(AND(MONTH(A2)>=5,MONTH(A2)<=9),"Peak","Off-Peak") -> Off-Peak | E2: =CHOOSE(WEEKDAY(A2,2),"Mon","Tue","Wed","Thu","Fri","Sat","Sun") -> Wed | F2: 91 | G2: 150 | H2: 11583.98 | I2: 131.84 | J2: =IF(G2=0,0,F2/G2) -> 0.60666667 | K2: =IF(F2=0,0,H2/F2) -> 127.29648 | L2: =IF(G2=0,0,H2/G2) -> 77.226533 | M2: =K2-I2 -> -4.5435165
A3: 45659 | B3: Liffey Quarter Hotel | C3: =CHOOSE(MONTH(A3),"Jan","Feb","Mar","Apr","May","Jun","Jul","Aug","Sep","Oct","Nov","Dec") -> Jan | D3: =IF(AND(MONTH(A3)>=5,MONTH(A3)<=9),"Peak","Off-Peak") -> Off-Peak | E3: =CHOOSE(WEEKDAY(A3,2),"Mon","Tue","Wed","Thu","Fri","Sat","Sun") -> Thu | F3: 99 | G3: 150 | H3: 14106.16 | I3: 135.18 | J3: =IF(G3=0,0,F3/G3) -> 0.66 | K3: =IF(F3=0,0,H3/F3) -> 142.48646 | L3: =IF(G3=0,0,H3/G3) -> 94.041067 | M3: =K3-I3 -> 7.3064646
A4: 45660 | B4: Liffey Quarter Hotel | C4: =CHOOSE(MONTH(A4),"Jan","Feb","Mar","Apr","May","Jun","Jul","Aug","Sep","Oct","Nov","Dec") -> Jan | D4: =IF(AND(MONTH(A4)>=5,MONTH(A4)<=9),"Peak","Off-Peak") -> Off-Peak | E4: =CHOOSE(WEEKDAY(A4,2),"Mon","Tue","Wed","Thu","Fri","Sat","Sun") -> Fri | F4: 101 | G4: 150 | H4: 13896.7 | I4: 139.94 | J4: =IF(G4=0,0,F4/G4) -> 0.67333333 | K4: =IF(F4=0,0,H4/F4) -> 137.59109 | L4: =IF(G4=0,0,H4/G4) -> 92.644667 | M4: =K4-I4 -> -2.3489109
A5: 45661 | B5: Liffey Quarter Hotel | C5: =CHOOSE(MONTH(A5),"Jan","Feb","Mar","Apr","May","Jun","Jul","Aug","Sep","Oct","Nov","Dec") -> Jan | D5: =IF(AND(MONTH(A5)>=5,MONTH(A5)<=9),"Peak","Off-Peak") -> Off-Peak | E5: =CHOOSE(WEEKDAY(A5,2),"Mon","Tue","Wed","Thu","Fri","Sat","Sun") -> Sat | F5: 104 | G5: 150 | H5: 14778.05 | I5: 136.53 | J5: =IF(G5=0,0,F5/G5) -> 0.69333333 | K5: =IF(F5=0,0,H5/F5) -> 142.09663 | L5: =IF(G5=0,0,H5/G5) -> 98.520333 | M5: =K5-I5 -> 5.5666346
A6: 45662 | B6: Liffey Quarter Hotel | C6: =CHOOSE(MONTH(A6),"Jan","Feb","Mar","Apr","May","Jun","Jul","Aug","Sep","Oct","Nov","Dec") -> Jan | D6: =IF(AND(MONTH(A6)>=5,MONTH(A6)<=9),"Peak","Off-Peak") -> Off-Peak | E6: =CHOOSE(WEEKDAY(A6,2),"Mon","Tue","Wed","Thu","Fri","Sat","Sun") -> Sun | F6: 85 | G6: 150 | H6: 10393.59 | I6: 128.96 | J6: =IF(G6=0,0,F6/G6) -> 0.56666667 | K6: =IF(F6=0,0,H6/F6) -> 122.27753 | L6: =IF(G6=0,0,H6/G6) -> 69.2906 | M6: =K6-I6 -> -6.6824706
A7: 45663 | B7: Liffey Quarter Hotel | C7: =CHOOSE(MONTH(A7),"Jan","Feb","Mar","Apr","May","Jun","Jul","Aug","Sep","Oct","Nov","Dec") -> Jan | D7: =IF(AND(MONTH(A7)>=5,MONTH(A7)<=9),"Peak","Off-Peak") -> Off-Peak | E7: =CHOOSE(WEEKDAY(A7,2),"Mon","Tue","Wed","Thu","Fri","Sat","Sun") -> Mon | F7: 88 | G7: 150 | H7: 10851.92 | I7: 126.54 | J7: =IF(G7=0,0,F7/G7) -> 0.58666667 | K7: =IF(F7=0,0,H7/F7) -> 123.31727 | L7: =IF(G7=0,0,H7/G7) -> 72.346133 | M7: =K7-I7 -> -3.2227273
A8: 45664 | B8: Liffey Quarter Hotel | C8: =CHOOSE(MONTH(A8),"Jan","Feb","Mar","Apr","May","Jun","Jul","Aug","Sep","Oct","Nov","Dec") -> Jan | D8: =IF(AND(MONTH(A8)>=5,MONTH(A8)<=9),"Peak","Off-Peak") -> Off-Peak | E8: =CHOOSE(WEEKDAY(A8,2),"Mon","Tue","Wed","Thu","Fri","Sat","Sun") -> Tue | F8: 94 | G8: 150 | H8: 12432.33 | I8: 135.57 | J8: =IF(G8=0,0,F8/G8) -> 0.62666667 | K8: =IF(F8=0,0,H8/F8) -> 132.25883 | L8: =IF(G8=0,0,H8/G8) -> 82.8822 | M8: =K8-I8 -> -3.3111702
A9: 45665 | B9: Liffey Quarter Hotel | C9: =CHOOSE(MONTH(A9),"Jan","Feb","Mar","Apr","May","Jun","Jul","Aug","Sep","Oct","Nov","Dec") -> Jan | D9: =IF(AND(MONTH(A9)>=5,MONTH(A9)<=9),"Peak","Off-Peak") -> Off-Peak | E9: =CHOOSE(WEEKDAY(A9,2),"Mon","Tue","Wed","Thu","Fri","Sat","Sun") -> Wed | F9: 95 | G9: 150 | H9: 11746.85 | I9: 129.61 | J9: =IF(G9=0,0,F9/G9) -> 0.63333333 | K9: =IF(F9=0,0,H9/F9) -> 123.65105 | L9: =IF(G9=0,0,H9/G9) -> 78.312333 | M9: =K9-I9 -> -5.9589474
A10: 45666 | B10: Liffey Quarter Hotel | C10: =CHOOSE(MONTH(A10),"Jan","Feb","Mar","Apr","May","Jun","Jul","Aug","Sep","Oct","Nov","Dec") -> Jan | D10: =IF(AND(MONTH(A10)>=5,MONTH(A10)<=9),"Peak","Off-Peak") -> Off-Peak | E10: =CHOOSE(WEEKDAY(A10,2),"Mon","Tue","Wed","Thu","Fri","Sat","Sun") -> Thu | F10: 94 | G10: 150 | H10: 13042.58 | I10: 133.07 | J10: =IF(G10=0,0,F10/G10) -> 0.62666667 | K10: =IF(F10=0,0,H10/F10) -> 138.75085 | L10: =IF(G10=0,0,H10/G10) -> 86.950533 | M10: =K10-I10 -> 5.6808511
A11: 45667 | B11: Liffey Quarter Hotel | C11: =CHOOSE(MONTH(A11),"Jan","Feb","Mar","Apr","May","Jun","Jul","Aug","Sep","Oct","Nov","Dec") -> Jan | D11: =IF(AND(MONTH(A11)>=5,MONTH(A11)<=9),"Peak","Off-Peak") -> Off-Peak | E11: =CHOOSE(WEEKDAY(A11,2),"Mon","Tue","Wed","Thu","Fri","Sat","Sun") -> Fri | F11: 99 | G11: 150 | H11: 13765.43 | I11: 141.97 | J11: =IF(G11=0,0,F11/G11) -> 0.66 | K11: =IF(F11=0,0,H11/F11) -> 139.04475 | L11: =IF(G11=0,0,H11/G11) -> 91.769533 | M11: =K11-I11 -> -2.9252525
A12: 45668 | B12: Liffey Quarter Hotel | C12: =CHOOSE(MONTH(A12),"Jan","Feb","Mar","Apr","May","Jun","Jul","Aug","Sep","Oct","Nov","Dec") -> Jan | D12: =IF(AND(MONTH(A12)>=5,MONTH(A12)<=9),"Peak","Off-Peak") -> Off-Peak | E12: =CHOOSE(WEEKDAY(A12,2),"Mon","Tue","Wed","Thu","Fri","Sat","Sun") -> Sat | F12: 110 | G12: 150 | H12: 15652.5 | I12: 140.62 | J12: =IF(G12=0,0,F12/G12) -> 0.73333333 | K12: =IF(F12=0,0,H12/F12) -> 142.29545 | L12: =IF(G12=0,0,H12/G12) -> 104.35 | M12: =K12-I12 -> 1.6754545
A13: 45669 | B13: Liffey Quarter Hotel | C13: =CHOOSE(MONTH(A13),"Jan","Feb","Mar","Apr","May","Jun","Jul","Aug","Sep","Oct","Nov","Dec") -> Jan | D13: =IF(AND(MONTH(A13)>=5,MONTH(A13)<=9),"Peak","Off-Peak") -> Off-Peak | E13: =CHOOSE(WEEKDAY(A13,2),"Mon","Tue","Wed","Thu","Fri","Sat","Sun") -> Sun | F13: 83 | G13: 150 | H13: 10428.29 | I13: 126.56 | J13: =IF(G13=0,0,F13/G13) -> 0.55333333 | K13: =IF(F13=0,0,H13/F13) -> 125.64205 | L13: =IF(G13=0,0,H13/G13) -> 69.521933 | M13: =K13-I13 -> -0.91795181
... A32: 45688 | B32: Liffey Quarter Hotel | C32: =CHOOSE(MONTH(A32),"Jan","Feb","Mar","Apr","May","Jun","Jul","Aug","Sep","Oct","Nov","Dec") -> Jan | D32: =IF(AND(MONTH(A32)>=5,MONTH(A32)<=9),"Peak","Off-Peak") -> Off-Peak | E32: =CHOOSE(WEEKDAY(A32,2),"Mon","Tue","Wed","Thu","Fri","Sat","Sun") -> Fri | F32: 105 | G32: 150 | H32: 15096.36 | I32: 140.26 | J32: =IF(G32=0,0,F32/G32) -> 0.7 | K32: =IF(F32=0,0,H32/F32) -> 143.77486 | L32: =IF(G32=0,0,H32/G32) -> 100.6424 | M32: =K32-I32 -> 3.5148571
A33: 45689 | B33: Liffey Quarter Hotel | C33: =CHOOSE(MONTH(A33),"Jan","Feb","Mar","Apr","May","Jun","Jul","Aug","Sep","Oct","Nov","Dec") -> Feb | D33: =IF(AND(MONTH(A33)>=5,MONTH(A33)<=9),"Peak","Off-Peak") -> Off-Peak | E33: =CHOOSE(WEEKDAY(A33,2),"Mon","Tue","Wed","Thu","Fri","Sat","Sun") -> Sat | F33: 125 | G33: 150 | H33: 20905.39 | I33: 160.44 | J33: =IF(G33=0,0,F33/G33) -> 0.83333333 | K33: =IF(F33=0,0,H33/F33) -> 167.24312 | L33: =IF(G33=0,0,H33/G33) -> 139.36927 | M33: =K33-I33 -> 6.80312 | N33: Rugby international weekend
A34: 45690 | B34: Liffey Quarter Hotel | C34: =CHOOSE(MONTH(A34),"Jan","Feb","Mar","Apr","May","Jun","Jul","Aug","Sep","Oct","Nov","Dec") -> Feb | D34: =IF(AND(MONTH(A34)>=5,MONTH(A34)<=9),"Peak","Off-Peak") -> Off-Peak | E34: =CHOOSE(WEEKDAY(A34,2),"Mon","Tue","Wed","Thu","Fri","Sat","Sun") -> Sun | F34: 89 | G34: 150 | H34: 10762.71 | I34: 133.33 | J34: =IF(G34=0,0,F34/G34) -> 0.59333333 | K34: =IF(F34=0,0,H34/F34) -> 120.92933 | L34: =IF(G34=0,0,H34/G34) -> 71.7514 | M34: =K34-I34 -> -12.400674
A35: 45691 | B35: Liffey Quarter Hotel | C35: =CHOOSE(MONTH(A35),"Jan","Feb","Mar","Apr","May","Jun","Jul","Aug","Sep","Oct","Nov","Dec") -> Feb | D35: =IF(AND(MONTH(A35)>=5,MONTH(A35)<=9),"Peak","Off-Peak") -> Off-Peak | E35: =CHOOSE(WEEKDAY(A35,2),"Mon","Tue","Wed","Thu","Fri","Sat","Sun") -> Mon | F35: 103 | G35: 150 | H35: 13137.26 | I35: 134.91 | J35: =IF(G35=0,0,F35/G35) -> 0.68666667 | K35: =IF(F35=0,0,H35/F35) -> 127.54621 | L35: =IF(G35=0,0,H35/G35) -> 87.581733 | M35: =K35-I35 -> -7.3637864
A36: 45692 | B36: Liffey Quarter Hotel | C36: =CHOOSE(MONTH(A36),"Jan","Feb","Mar","Apr","May","Jun","Jul","Aug","Sep","Oct","Nov","Dec") -> Feb | D36: =IF(AND(MONTH(A36)>=5,MONTH(A36)<=9),"Peak","Off-Peak") -> Off-Peak | E36: =CHOOSE(WEEKDAY(A36,2),"Mon","Tue","Wed","Thu","Fri","Sat","Sun") -> Tue | F36: 101 | G36: 150 | H36: 13045.17 | I36: 133.41 | J36: =IF(G36=0,0,F36/G36) -> 0.67333333 | K36: =IF(F36=0,0,H36/F36) -> 129.1601 | L36: =IF(G36=0,0,H36/G36) -> 86.9678 | M36: =K36-I36 -> -4.249901
A37: 45693 | B37: Liffey Quarter Hotel | C37: =CHOOSE(MONTH(A37),"Jan","Feb","Mar","Apr","May","Jun","Jul","Aug","Sep","Oct","Nov","Dec") -> Feb | D37: =IF(AND(MONTH(A37)>=5,MONTH(A37)<=9),"Peak","Off-Peak") -> Off-Peak | E37: =CHOOSE(WEEKDAY(A37,2),"Mon","Tue","Wed","Thu","Fri","Sat","Sun") -> Wed | F37: 105 | G37: 150 | H37: 13341.52 | I37: 138.89 | J37: =IF(G37=0,0,F37/G37) -> 0.7 | K37: =IF(F37=0,0,H37/F37) -> 127.0621 | L37: =IF(G37=0,0,H37/G37) -> 88.943467 | M37: =K37-I37 -> -11.827905
A38: 45694 | B38: Liffey Quarter Hotel | C38: =CHOOSE(MONTH(A38),"Jan","Feb","Mar","Apr","May","Jun","Jul","Aug","Sep","Oct","Nov","Dec") -> Feb | D38: =IF(AND(MONTH(A38)>=5,MONTH(A38)<=9),"Peak","Off-Peak") -> Off-Peak | E38: =CHOOSE(WEEKDAY(A38,2),"Mon","Tue","Wed","Thu","Fri","Sat","Sun") -> Thu | F38: 110 | G38: 150 | H38: 14316.87 | I38: 137.99 | J38: =IF(G38=0,0,F38/G38) -> 0.73333333 | K38: =IF(F38=0,0,H38/F38) -> 130.15336 | L38: =IF(G38=0,0,H38/G38) -> 95.4458 | M38: =K38-I38 -> -7.8366364
A39: 45695 | B39: Liffey Quarter Hotel | C39: =CHOOSE(MONTH(A39),"Jan","Feb","Mar","Apr","May","Jun","Jul","Aug","Sep","Oct","Nov","Dec") -> Feb | D39: =IF(AND(MONTH(A39)>=5,MONTH(A39)<=9),"Peak","Off-Peak") -> Off-Peak | E39: =CHOOSE(WEEKDAY(A39,2),"Mon","Tue","Wed","Thu","Fri","Sat","Sun") -> Fri | F39: 110 | G39: 150 | H39: 16013.15 | I39: 143.38 | J39: =IF(G39=0,0,F39/G39) -> 0.73333333 | K39: =IF(F39=0,0,H39/F39) -> 145.57409 | L39: =IF(G39=0,0,H39/G39) -> 106.75433 | M39: =K39-I39 -> 2.1940909
A40: 45696 | B40: Liffey Quarter Hotel | C40: =CHOOSE(MONTH(A40),"Jan","Feb","Mar","Apr","May","Jun","Jul","Aug","Sep","Oct","Nov","Dec") -> Feb | D40: =IF(AND(MONTH(A40)>=5,MONTH(A40)<=9),"Peak","Off-Peak") -> Off-Peak | E40: =CHOOSE(WEEKDAY(A40,2),"Mon","Tue","Wed","Thu","Fri","Sat","Sun") -> Sat | F40: 111 | G40: 150 | H40: 15549.01 | I40: 145.17 | J40: =IF(G40=0,0,F40/G40) -> 0.74 | K40: =IF(F40=0,0,H40/F40) -> 140.08117 | L40: =IF(G40=0,0,H40/G40) -> 103.66007 | M40: =K40-I40 -> -5.0888288
A41: 45697 | B41: Liffey Quarter Hotel | C41: =CHOOSE(MONTH(A41),"Jan","Feb","Mar","Apr","May","Jun","Jul","Aug","Sep","Oct","Nov","Dec") -> Feb | D41: =IF(AND(MONTH(A41)>=5,MONTH(A41)<=9),"Peak","Off-Peak") -> Off-Peak | E41: =CHOOSE(WEEKDAY(A41,2),"Mon","Tue","Wed","Thu","Fri","Sat","Sun") -> Sun | F41: 96 | G41: 150 | H41: 12030.09 | I41: 131.29 | J41: =IF(G41=0,0,F41/G41) -> 0.64 | K41: =IF(F41=0,0,H41/F41) -> 125.31344 | L41: =IF(G41=0,0,H41/G41) -> 80.2006 | M41: =K41-I41 -> -5.9765625
A42: 45698 | B42: Liffey Quarter Hotel | C42: =CHOOSE(MONTH(A42),"Jan","Feb","Mar","Apr","May","Jun","Jul","Aug","Sep","Oct","Nov","Dec") -> Feb | D42: =IF(AND(MONTH(A42)>=5,MONTH(A42)<=9),"Peak","Off-Peak") -> Off-Peak | E42: =CHOOSE(WEEKDAY(A42,2),"Mon","Tue","Wed","Thu","Fri","Sat","Sun") -> Mon | F42: 99 | G42: 150 | H42: 12410.48 | I42: 128.91 | J42: =IF(G42=0,0,F42/G42) -> 0.66 | K42: =IF(F42=0,0,H42/F42) -> 125.35838 | L42: =IF(G42=0,0,H42/G42) -> 82.736533 | M42: =K42-I42 -> -3.5516162
A43: 45699 | B43: Liffey Quarter Hotel | C43: =CHOOSE(MONTH(A43),"Jan","Feb","Mar","Apr","May","Jun","Jul","Aug","Sep","Oct","Nov","Dec") -> Feb | D43: =IF(AND(MONTH(A43)>=5,MONTH(A43)<=9),"Peak","Off-Peak") -> Off-Peak | E43: =CHOOSE(WEEKDAY(A43,2),"Mon","Tue","Wed","Thu","Fri","Sat","Sun") -> Tue | F43: 100 | G43: 150 | H43: 12771.37 | I43: 133.47 | J43: =IF(G43=0,0,F43/G43) -> 0.66666667 | K43: =IF(F43=0,0,H43/F43) -> 127.7137 | L43: =IF(G43=0,0,H43/G43) -> 85.142467 | M43: =K43-I43 -> -5.7563
A44: 45700 | B44: Liffey Quarter Hotel | C44: =CHOOSE(MONTH(A44),"Jan","Feb","Mar","Apr","May","Jun","Jul","Aug","Sep","Oct","Nov","Dec") -> Feb | D44: =IF(AND(MONTH(A44)>=5,MONTH(A44)<=9),"Peak","Off-Peak") -> Off-Peak | E44: =CHOOSE(WEEKDAY(A44,2),"Mon","Tue","Wed","Thu","Fri","Sat","Sun") -> Wed | F44: 102 | G44: 150 | H44: 14217.62 | I44: 142.22 | J44: =IF(G44=0,0,F44/G44) -> 0.68 | K44: =IF(F44=0,0,H44/F44) -> 139.38843 | L44: =IF(G44=0,0,H44/G44) -> 94.784133 | M44: =K44-I44 -> -2.8315686
A45: 45701 | B45: Liffey Quarter Hotel | C45: =CHOOSE(MONTH(A45),"Jan","Feb","Mar","Apr","May","Jun","Jul","Aug","Sep","Oct","Nov","Dec") -> Feb | D45: =IF(AND(MONTH(A45)>=5,MONTH(A45)<=9),"Peak","Off-Peak") -> Off-Peak | E45: =CHOOSE(WEEKDAY(A45,2),"Mon","Tue","Wed","Thu","Fri","Sat","Sun") -> Thu | F45: 106 | G45: 150 | H45: 14620.51 | I45: 138.59 | J45: =IF(G45=0,0,F45/G45) -> 0.70666667 | K45: =IF(F45=0,0,H45/F45) -> 137.92934 | L45: =IF(G45=0,0,H45/G45) -> 97.470067 | M45: =K45-I45 -> -0.66066038
... A73: 45729 | B73: Liffey Quarter Hotel | C73: =CHOOSE(MONTH(A73),"Jan","Feb","Mar","Apr","May","Jun","Jul","Aug","Sep","Oct","Nov","Dec") -> Mar | D73: =IF(AND(MONTH(A73)>=5,MONTH(A73)<=9),"Peak","Off-Peak") -> Off-Peak | E73: =CHOOSE(WEEKDAY(A73,2),"Mon","Tue","Wed","Thu","Fri","Sat","Sun") -> Thu | F73: 120 | G73: 150 | H73: 18115.73 | I73: 152.47 | J73: =IF(G73=0,0,F73/G73) -> 0.8 | K73: =IF(F73=0,0,H73/F73) -> 150.96442 | L73: =IF(G73=0,0,H73/G73) -> 120.77153 | M73: =K73-I73 -> -1.5055833
A74: 45730 | B74: Liffey Quarter Hotel | C74: =CHOOSE(MONTH(A74),"Jan","Feb","Mar","Apr","May","Jun","Jul","Aug","Sep","Oct","Nov","Dec") -> Mar | D74: =IF(AND(MONTH(A74)>=5,MONTH(A74)<=9),"Peak","Off-Peak") -> Off-Peak | E74: =CHOOSE(WEEKDAY(A74,2),"Mon","Tue","Wed","Thu","Fri","Sat","Sun") -> Fri | F74: 139 | G74: 150 | H74: 27020.26 | I74: 189.72 | J74: =IF(G74=0,0,F74/G74) -> 0.92666667 | K74: =IF(F74=0,0,H74/F74) -> 194.39036 | L74: =IF(G74=0,0,H74/G74) -> 180.13507 | M74: =K74-I74 -> 4.6703597 | N74: St Patrick's Festival
A75: 45731 | B75: Liffey Quarter Hotel | C75: =CHOOSE(MONTH(A75),"Jan","Feb","Mar","Apr","May","Jun","Jul","Aug","Sep","Oct","Nov","Dec") -> Mar | D75: =IF(AND(MONTH(A75)>=5,MONTH(A75)<=9),"Peak","Off-Peak") -> Off-Peak | E75: =CHOOSE(WEEKDAY(A75,2),"Mon","Tue","Wed","Thu","Fri","Sat","Sun") -> Sat | F75: 143 | G75: 150 | H75: 26338.95 | I75: 189.97 | J75: =IF(G75=0,0,F75/G75) -> 0.95333333 | K75: =IF(F75=0,0,H75/F75) -> 184.18846 | L75: =IF(G75=0,0,H75/G75) -> 175.593 | M75: =K75-I75 -> -5.7815385 | N75: St Patrick's Festival
A76: 45732 | B76: Liffey Quarter Hotel | C76: =CHOOSE(MONTH(A76),"Jan","Feb","Mar","Apr","May","Jun","Jul","Aug","Sep","Oct","Nov","Dec") -> Mar | D76: =IF(AND(MONTH(A76)>=5,MONTH(A76)<=9),"Peak","Off-Peak") -> Off-Peak | E76: =CHOOSE(WEEKDAY(A76,2),"Mon","Tue","Wed","Thu","Fri","Sat","Sun") -> Sun | F76: 125 | G76: 150 | H76: 23171.58 | I76: 173.74 | J76: =IF(G76=0,0,F76/G76) -> 0.83333333 | K76: =IF(F76=0,0,H76/F76) -> 185.37264 | L76: =IF(G76=0,0,H76/G76) -> 154.4772 | M76: =K76-I76 -> 11.63264 | N76: St Patrick's Festival
A77: 45733 | B77: Liffey Quarter Hotel | C77: =CHOOSE(MONTH(A77),"Jan","Feb","Mar","Apr","May","Jun","Jul","Aug","Sep","Oct","Nov","Dec") -> Mar | D77: =IF(AND(MONTH(A77)>=5,MONTH(A77)<=9),"Peak","Off-Peak") -> Off-Peak | E77: =CHOOSE(WEEKDAY(A77,2),"Mon","Tue","Wed","Thu","Fri","Sat","Sun") -> Mon | F77: 126 | G77: 150 | H77: 22981.7 | I77: 171.51 | J77: =IF(G77=0,0,F77/G77) -> 0.84 | K77: =IF(F77=0,0,H77/F77) -> 182.39444 | L77: =IF(G77=0,0,H77/G77) -> 153.21133 | M77: =K77-I77 -> 10.884444 | N77: St Patrick's Festival
A78: 45734 | B78: Liffey Quarter Hotel | C78: =CHOOSE(MONTH(A78),"Jan","Feb","Mar","Apr","May","Jun","Jul","Aug","Sep","Oct","Nov","Dec") -> Mar | D78: =IF(AND(MONTH(A78)>=5,MONTH(A78)<=9),"Peak","Off-Peak") -> Off-Peak | E78: =CHOOSE(WEEKDAY(A78,2),"Mon","Tue","Wed","Thu","Fri","Sat","Sun") -> Tue | F78: 107 | G78: 150 | H78: 14572.01 | I78: 146.98 | J78: =IF(G78=0,0,F78/G78) -> 0.71333333 | K78: =IF(F78=0,0,H78/F78) -> 136.18701 | L78: =IF(G78=0,0,H78/G78) -> 97.146733 | M78: =K78-I78 -> -10.792991
A79: 45735 | B79: Liffey Quarter Hotel | C79: =CHOOSE(MONTH(A79),"Jan","Feb","Mar","Apr","May","Jun","Jul","Aug","Sep","Oct","Nov","Dec") -> Mar | D79: =IF(AND(MONTH(A79)>=5,MONTH(A79)<=9),"Peak","Off-Peak") -> Off-Peak | E79: =CHOOSE(WEEKDAY(A79,2),"Mon","Tue","Wed","Thu","Fri","Sat","Sun") -> Wed | F79: 118 | G79: 150 | H79: 17008.69 | I79: 148.96 | J79: =IF(G79=0,0,F79/G79) -> 0.78666667 | K79: =IF(F79=0,0,H79/F79) -> 144.14144 | L79: =IF(G79=0,0,H79/G79) -> 113.39127 | M79: =K79-I79 -> -4.8185593
A80: 45736 | B80: Liffey Quarter Hotel | C80: =CHOOSE(MONTH(A80),"Jan","Feb","Mar","Apr","May","Jun","Jul","Aug","Sep","Oct","Nov","Dec") -> Mar | D80: =IF(AND(MONTH(A80)>=5,MONTH(A80)<=9),"Peak","Off-Peak") -> Off-Peak | E80: =CHOOSE(WEEKDAY(A80,2),"Mon","Tue","Wed","Thu","Fri","Sat","Sun") -> Thu | F80: 114 | G80: 150 | H80: 16381.49 | I80: 152.26 | J80: =IF(G80=0,0,F80/G80) -> 0.76 | K80: =IF(F80=0,0,H80/F80) -> 143.69728 | L80: =IF(G80=0,0,H80/G80) -> 109.20993 | M80: =K80-I80 -> -8.5627193
A81: 45737 | B81: Liffey Quarter Hotel | C81: =CHOOSE(MONTH(A81),"Jan","Feb","Mar","Apr","May","Jun","Jul","Aug","Sep","Oct","Nov","Dec") -> Mar | D81: =IF(AND(MONTH(A81)>=5,MONTH(A81)<=9),"Peak","Off-Peak") -> Off-Peak | E81: =CHOOSE(WEEKDAY(A81,2),"Mon","Tue","Wed","Thu","Fri","Sat","Sun") -> Fri | F81: 124 | G81: 150 | H81: 19629.7 | I81: 155.57 | J81: =IF(G81=0,0,F81/G81) -> 0.82666667 | K81: =IF(F81=0,0,H81/F81) -> 158.30403 | L81: =IF(G81=0,0,H81/G81) -> 130.86467 | M81: =K81-I81 -> 2.7340323
A82: 45738 | B82: Liffey Quarter Hotel | C82: =CHOOSE(MONTH(A82),"Jan","Feb","Mar","Apr","May","Jun","Jul","Aug","Sep","Oct","Nov","Dec") -> Mar | D82: =IF(AND(MONTH(A82)>=5,MONTH(A82)<=9),"Peak","Off-Peak") -> Off-Peak | E82: =CHOOSE(WEEKDAY(A82,2),"Mon","Tue","Wed","Thu","Fri","Sat","Sun") -> Sat | F82: 133 | G82: 150 | H82: 24151.08 | I82: 177.48 | J82: =IF(G82=0,0,F82/G82) -> 0.88666667 | K82: =IF(F82=0,0,H82/F82) -> 181.58707 | L82: =IF(G82=0,0,H82/G82) -> 161.0072 | M82: =K82-I82 -> 4.1070677 | N82: Rugby international weekend
A83: 45739 | B83: Liffey Quarter Hotel | C83: =CHOOSE(MONTH(A83),"Jan","Feb","Mar","Apr","May","Jun","Jul","Aug","Sep","Oct","Nov","Dec") -> Mar | D83: =IF(AND(MONTH(A83)>=5,MONTH(A83)<=9),"Peak","Off-Peak") -> Off-Peak | E83: =CHOOSE(WEEKDAY(A83,2),"Mon","Tue","Wed","Thu","Fri","Sat","Sun") -> Sun | F83: 103 | G83: 150 | H83: 14580.26 | I83: 142.37 | J83: =IF(G83=0,0,F83/G83) -> 0.68666667 | K83: =IF(F83=0,0,H83/F83) -> 141.55592 | L83: =IF(G83=0,0,H83/G83) -> 97.201733 | M83: =K83-I83 -> -0.81407767
A84: 45740 | B84: Liffey Quarter Hotel | C84: =CHOOSE(MONTH(A84),"Jan","Feb","Mar","Apr","May","Jun","Jul","Aug","Sep","Oct","Nov","Dec") -> Mar | D84: =IF(AND(MONTH(A84)>=5,MONTH(A84)<=9),"Peak","Off-Peak") -> Off-Peak | E84: =CHOOSE(WEEKDAY(A84,2),"Mon","Tue","Wed","Thu","Fri","Sat","Sun") -> Mon | F84: 107 | G84: 150 | H84: 15189.74 | I84: 143.37 | J84: =IF(G84=0,0,F84/G84) -> 0.71333333 | K84: =IF(F84=0,0,H84/F84) -> 141.96019 | L84: =IF(G84=0,0,H84/G84) -> 101.26493 | M84: =K84-I84 -> -1.4098131
A85: 45741 | B85: Liffey Quarter Hotel | C85: =CHOOSE(MONTH(A85),"Jan","Feb","Mar","Apr","May","Jun","Jul","Aug","Sep","Oct","Nov","Dec") -> Mar | D85: =IF(AND(MONTH(A85)>=5,MONTH(A85)<=9),"Peak","Off-Peak") -> Off-Peak | E85: =CHOOSE(WEEKDAY(A85,2),"Mon","Tue","Wed","Thu","Fri","Sat","Sun") -> Tue | F85: 109 | G85: 150 | H85: 16689.71 | I85: 145.95 | J85: =IF(G85=0,0,F85/G85) -> 0.72666667 | K85: =IF(F85=0,0,H85/F85) -> 153.11661 | L85: =IF(G85=0,0,H85/G85) -> 111.26473 | M85: =K85-I85 -> 7.1666055
...

Sheet Monthly Data
A1: Choose Hotel: | B1: =Dashboard!$B$6 -> Hotel California | H1: =IF(Dashboard!$B$6="All Properties","*",Dashboard!$B$6) -> Hotel California
A3: Month | B3: Rooms Sold | C3: Rooms Available | D3: Room Revenue (€) | E3: Occupancy % | F3: ADR (€) | G3: RevPAR (€) | H3: CompSet Avg Rate (€) | I3: Rate Variance (€) | J3: Rate Index (ADR/CompSet ×100)
A4: Jan | B4: =SUMIFS(HotelData[Rooms Sold],HotelData[Month],$A4,HotelData[Property],$H$1) -> 3158 | C4: =SUMIFS(HotelData[Total Rooms Available],HotelData[Month],$A4,HotelData[Property],$H$1) -> 3875 | D4: =SUMIFS(HotelData[Room Revenue (€)],HotelData[Month],$A4,HotelData[Property],$H$1) -> 773257 | E4: =IF(C4=0,0,B4/C4) -> 0.81496774 | F4: =IF(B4=0,0,D4/B4) -> 244.85655 | G4: =IF(C4=0,0,D4/C4) -> 199.55019 | H4: =AVERAGEIFS(HotelData[Competitor Set Avg Rate (€)],HotelData[Month],$A4,HotelData[Property],$H$1) -> 187.09677 | I4: =F4-H4 -> 57.759781 | J4: =IF(H4=0,0,F4/H4*100) -> 130.87161
A5: Feb | B5: =SUMIFS(HotelData[Rooms Sold],HotelData[Month],$A5,HotelData[Property],$H$1) -> 2951 | C5: =SUMIFS(HotelData[Total Rooms Available],HotelData[Month],$A5,HotelData[Property],$H$1) -> 3500 | D5: =SUMIFS(HotelData[Room Revenue (€)],HotelData[Month],$A5,HotelData[Property],$H$1) -> 670944 | E5: =IF(C5=0,0,B5/C5) -> 0.84314286 | F5: =IF(B5=0,0,D5/B5) -> 227.36157 | G5: =IF(C5=0,0,D5/C5) -> 191.69829 | H5: =AVERAGEIFS(HotelData[Competitor Set Avg Rate (€)],HotelData[Month],$A5,HotelData[Property],$H$1) -> 179.78571 | I5: =F5-H5 -> 47.575858 | J5: =IF(H5=0,0,F5/H5*100) -> 126.46254
A6: Mar | B6: =SUMIFS(HotelData[Rooms Sold],HotelData[Month],$A6,HotelData[Property],$H$1) -> 3137 | C6: =SUMIFS(HotelData[Total Rooms Available],HotelData[Month],$A6,HotelData[Property],$H$1) -> 3875 | D6: =SUMIFS(HotelData[Room Revenue (€)],HotelData[Month],$A6,HotelData[Property],$H$1) -> 745712 | E6: =IF(C6=0,0,B6/C6) -> 0.80954839 | F6: =IF(B6=0,0,D6/B6) -> 237.71501 | G6: =IF(C6=0,0,D6/C6) -> 192.44181 | H6: =AVERAGEIFS(HotelData[Competitor Set Avg Rate (€)],HotelData[Month],$A6,HotelData[Property],$H$1) -> 192.51613 | I6: =F6-H6 -> 45.198885 | J6: =IF(H6=0,0,F6/H6*100) -> 123.47797
A7: Apr | B7: =SUMIFS(HotelData[Rooms Sold],HotelData[Month],$A7,HotelData[Property],$H$1) -> 3135 | C7: =SUMIFS(HotelData[Total Rooms Available],HotelData[Month],$A7,HotelData[Property],$H$1) -> 3750 | D7: =SUMIFS(HotelData[Room Revenue (€)],HotelData[Month],$A7,HotelData[Property],$H$1) -> 588293 | E7: =IF(C7=0,0,B7/C7) -> 0.836 | F7: =IF(B7=0,0,D7/B7) -> 187.65327 | G7: =IF(C7=0,0,D7/C7) -> 156.87813 | H7: =AVERAGEIFS(HotelData[Competitor Set Avg Rate (€)],HotelData[Month],$A7,HotelData[Property],$H$1) -> 173.5 | I7: =F7-H7 -> 14.15327 | J7: =IF(H7=0,0,F7/H7*100) -> 108.1575
A8: May | B8: =SUMIFS(HotelData[Rooms Sold],HotelData[Month],$A8,HotelData[Property],$H$1) -> 3170 | C8: =SUMIFS(HotelData[Total Rooms Available],HotelData[Month],$A8,HotelData[Property],$H$1) -> 3875 | D8: =SUMIFS(HotelData[Room Revenue (€)],HotelData[Month],$A8,HotelData[Property],$H$1) -> 650539 | E8: =IF(C8=0,0,B8/C8) -> 0.81806452 | F8: =IF(B8=0,0,D8/B8) -> 205.21735 | G8: =IF(C8=0,0,D8/C8) -> 167.88103 | H8: =AVERAGEIFS(HotelData[Competitor Set Avg Rate (€)],HotelData[Month],$A8,HotelData[Property],$H$1) -> 180.03226 | I8: =F8-H8 -> 25.185092 | J8: =IF(H8=0,0,F8/H8*100) -> 113.98921
A9: Jun | B9: =SUMIFS(HotelData[Rooms Sold],HotelData[Month],$A9,HotelData[Property],$H$1) -> 3077 | C9: =SUMIFS(HotelData[Total Rooms Available],HotelData[Month],$A9,HotelData[Property],$H$1) -> 3750 | D9: =SUMIFS(HotelData[Room Revenue (€)],HotelData[Month],$A9,HotelData[Property],$H$1) -> 617874 | E9: =IF(C9=0,0,B9/C9) -> 0.82053333 | F9: =IF(B9=0,0,D9/B9) -> 200.80403 | G9: =IF(C9=0,0,D9/C9) -> 164.7664 | H9: =AVERAGEIFS(HotelData[Competitor Set Avg Rate (€)],HotelData[Month],$A9,HotelData[Property],$H$1) -> 188.4 | I9: =F9-H9 -> 12.40403 | J9: =IF(H9=0,0,F9/H9*100) -> 106.58388
A10: Jul | B10: =SUMIFS(HotelData[Rooms Sold],HotelData[Month],$A10,HotelData[Property],$H$1) -> 3221 | C10: =SUMIFS(HotelData[Total Rooms Available],HotelData[Month],$A10,HotelData[Property],$H$1) -> 3875 | D10: =SUMIFS(HotelData[Room Revenue (€)],HotelData[Month],$A10,HotelData[Property],$H$1) -> 660406 | E10: =IF(C10=0,0,B10/C10) -> 0.83122581 | F10: =IF(B10=0,0,D10/B10) -> 205.03136 | G10: =IF(C10=0,0,D10/C10) -> 170.42735 | H10: =AVERAGEIFS(HotelData[Competitor Set Avg Rate (€)],HotelData[Month],$A10,HotelData[Property],$H$1) -> 181.58065 | I10: =F10-H10 -> 23.450712 | J10: =IF(H10=0,0,F10/H10*100) -> 112.91476
A11: Aug | B11: =SUMIFS(HotelData[Rooms Sold],HotelData[Month],$A11,HotelData[Property],$H$1) -> 3242 | C11: =SUMIFS(HotelData[Total Rooms Available],HotelData[Month],$A11,HotelData[Property],$H$1) -> 3875 | D11: =SUMIFS(HotelData[Room Revenue (€)],HotelData[Month],$A11,HotelData[Property],$H$1) -> 796164 | E11: =IF(C11=0,0,B11/C11) -> 0.83664516 | F11: =IF(B11=0,0,D11/B11) -> 245.57804 | G11: =IF(C11=0,0,D11/C11) -> 205.46168 | H11: =AVERAGEIFS(HotelData[Competitor Set Avg Rate (€)],HotelData[Month],$A11,HotelData[Property],$H$1) -> 188.64516 | I11: =F11-H11 -> 56.932877 | J11: =IF(H11=0,0,F11/H11*100) -> 130.17988
A12: Sep | B12: =SUMIFS(HotelData[Rooms Sold],HotelData[Month],$A12,HotelData[Property],$H$1) -> 3052 | C12: =SUMIFS(HotelData[Total Rooms Available],HotelData[Month],$A12,HotelData[Property],$H$1) -> 3750 | D12: =SUMIFS(HotelData[Room Revenue (€)],HotelData[Month],$A12,HotelData[Property],$H$1) -> 653256 | E12: =IF(C12=0,0,B12/C12) -> 0.81386667 | F12: =IF(B12=0,0,D12/B12) -> 214.04194 | G12: =IF(C12=0,0,D12/C12) -> 174.2016 | H12: =AVERAGEIFS(HotelData[Competitor Set Avg Rate (€)],HotelData[Month],$A12,HotelData[Property],$H$1) -> 195.83333 | I12: =F12-H12 -> 18.208606 | J12: =IF(H12=0,0,F12/H12*100) -> 109.29801
A13: Oct | B13: =SUMIFS(HotelData[Rooms Sold],HotelData[Month],$A13,HotelData[Property],$H$1) -> 3117 | C13: =SUMIFS(HotelData[Total Rooms Available],HotelData[Month],$A13,HotelData[Property],$H$1) -> 3875 | D13: =SUMIFS(HotelData[Room Revenue (€)],HotelData[Month],$A13,HotelData[Property],$H$1) -> 778730 | E13: =IF(C13=0,0,B13/C13) -> 0.8043871 | F13: =IF(B13=0,0,D13/B13) -> 249.83317 | G13: =IF(C13=0,0,D13/C13) -> 200.96258 | H13: =AVERAGEIFS(HotelData[Competitor Set Avg Rate (€)],HotelData[Month],$A13,HotelData[Property],$H$1) -> 184.12903 | I13: =F13-H13 -> 65.704141 | J13: =IF(H13=0,0,F13/H13*100) -> 135.68375
A14: Nov | B14: =SUMIFS(HotelData[Rooms Sold],HotelData[Month],$A14,HotelData[Property],$H$1) -> 3133 | C14: =SUMIFS(HotelData[Total Rooms Available],HotelData[Month],$A14,HotelData[Property],$H$1) -> 3750 | D14: =SUMIFS(HotelData[Room Revenue (€)],HotelData[Month],$A14,HotelData[Property],$H$1) -> 663589 | E14: =IF(C14=0,0,B14/C14) -> 0.83546667 | F14: =IF(B14=0,0,D14/B14) -> 211.80626 | G14: =IF(C14=0,0,D14/C14) -> 176.95707 | H14: =AVERAGEIFS(HotelData[Competitor Set Avg Rate (€)],HotelData[Month],$A14,HotelData[Property],$H$1) -> 181.06667 | I14: =F14-H14 -> 30.739589 | J14: =IF(H14=0,0,F14/H14*100) -> 116.97695
A15: Dec | B15: =SUMIFS(HotelData[Rooms Sold],HotelData[Month],$A15,HotelData[Property],$H$1) -> 3177 | C15: =SUMIFS(HotelData[Total Rooms Available],HotelData[Month],$A15,HotelData[Property],$H$1) -> 3875 | D15: =SUMIFS(HotelData[Room Revenue (€)],HotelData[Month],$A15,HotelData[Property],$H$1) -> 671483 | E15: =IF(C15=0,0,B15/C15) -> 0.81987097 | F15: =IF(B15=0,0,D15/B15) -> 211.35757 | G15: =IF(C15=0,0,D15/C15) -> 173.28594 | H15: =AVERAGEIFS(HotelData[Competitor Set Avg Rate (€)],HotelData[Month],$A15,HotelData[Property],$H$1) -> 184.58065 | I15: =F15-H15 -> 26.776925 | J15: =IF(H15=0,0,F15/H15*100) -> 114.5069
A16: Full Year | B16: =SUM(B4:B15) -> 37570 | C16: =SUM(C4:C15) -> 45625 | D16: =SUM(D4:D15) -> 8270247 | E16: =IF(C16=0,0,B16/C16) -> 0.82345205 | F16: =IF(B16=0,0,D16/B16) -> 220.12901 | G16: =IF(C16=0,0,D16/C16) -> 181.26569 | H16: =AVERAGEIFS(HotelData[Competitor Set Avg Rate (€)],HotelData[Property],$H$1) -> 184.80548 | I16: =F16-H16 -> 35.323533 | J16: =IF(H16=0,0,F16/H16*100) -> 119.1139

Sheet Info
A2: Glossary:
A3: ADR - Average Daily Rate (€)
A4: RevPAR - Revenue Per Available Room
A5: CompSet - Competitor Set Rates
